Traceback (most recent call last):
  File "/Users/estyle-109/opt/anaconda3/envs/wandb-env/lib/python3.9/site-packages/wandb/sdk/wandb_config.py", line 166, in __getattr__
    return self.__getitem__(key)
  File "/Users/estyle-109/opt/anaconda3/envs/wandb-env/lib/python3.9/site-packages/wandb/sdk/wandb_config.py", line 133, in __getitem__
    return self._items[key]
KeyError: 'lr'
The above exception was the direct cause of the following exception:
Traceback (most recent call last):
  File "/Users/estyle-109/workspace/Confluence/MachineLearning/wandb/tutorial/tutorial.py", line 45, in <module>
    main()
  File "/Users/estyle-109/workspace/Confluence/MachineLearning/wandb/tutorial/tutorial.py", line 28, in main
    lr  =  wandb.config.lr
  File "/Users/estyle-109/opt/anaconda3/envs/wandb-env/lib/python3.9/site-packages/wandb/sdk/wandb_config.py", line 168, in __getattr__
    raise AttributeError(
AttributeError: '<class 'wandb.sdk.wandb_config.Config'>' object has no attribute 'lr'